<?xml version="1.0"?>
 <robot name="antares">

   <material name="white">
        <color rgba="1 1 1 1"/>
   </material>

   <link name="base_link">
     <visual>
       <geometry>
           <mesh filename="package://antares_model/meshes/body_visual_simple.stl"/>
           <box size="0,23 0,115 0,235"/>
       </geometry>
       <material name="white"/>
     </visual>
     <collision>
        <origin rpy="0 0 0" xyz="0,17773 -0,079752 0,56967"/>
        <geometry>
           <box size="0,23 0,115 0,235"/>
        </geometry>
     </collision>
   </link>

   <joint name="head_yaw" type="continuous">
     <origin rpy="0 0 0" xyz="0.17762 -0.086853 0.72319"/>
     <parent link="base_link"/>
     <child link="neck"/>
     <axis xyz="0 0 1"/>
   </joint>

   <link name="neck">
     <visual>
     <origin rpy="0 0 0" xyz="-0,17762 0,08653 -0,72139"/>
       <geometry>
         <mesh filename="package://antares_model/meshes/neck_visual_simple.stl"/>
       </geometry>
       <material name="white"/>
     </visual>
     <collision>
        <origin rpy="0 0 0" xyz="0 0 0"/>
        <geometry>
           <box size="0,034 0,035 0,07"/>
        </geometry>
     </collision>
   </link>


   <joint name="head_pitch" type="continuous">
     <origin rpy="0 0 0" xyz="0 0 0.022976"/>
     <parent link="neck"/>
     <child link="head"/>
     <axis xyz="1 0 0"/>
   </joint>

   <link name="head">
	   <visual>
		<origin rpy="0 0 0" xyz="-0,17762 0,08653 -0,74617"/>
       		<geometry>
         		<mesh filename="package://antares_model/meshes/head_visual_simple.stl"/>
       		</geometry>
       		<material name="white"/>
	   </visual>
       <collision>
        <origin rpy="0 0 0" xyz="0 -0,01 0,015"/>
        <geometry>
           <box size="0,07 0,12 0,037"/>
        </geometry>
     </collision>
   </link>

   <joint name="pelvis_yaw_l" type="continuous">
     <origin rpy="0 0 0" xyz="0.26206 -0.099753 0.43020"/>
     <parent link="base_link"/>
     <child link="pelvis_l"/>
     <axis xyz="0 0 1"/>
   </joint>

   <link name="pelvis_l">
	   <visual>
		<origin rpy="0 0 0" xyz="-0,26206 0,099753 -0,43020"/>
       		<geometry>
         		<mesh filename="package://antares_model/meshes/pelvis_l_visual_simple.stl"/>
       		</geometry>
       		<material name="white"/>
	   </visual>
       <collision>
        <origin rpy="0 0 0" xyz="0 0 0"/>
        <geometry>
           <box size="0,053 0,064 0,04"/>
        </geometry>
     </collision>
   </link>
   
   <joint name="pelvis_yaw_r" type="continuous">
     <origin rpy="0 0 0" xyz="0.093392 -0.099753 0.43020"/>
     <parent link="base_link"/>
     <child link="pelvis_r"/>
     <axis xyz="0 0 1"/>
   </joint>

   <link name="pelvis_r">
	   <visual>
		<origin rpy="0 0 0" xyz="-0,093392 0,099753 -0,43020"/>
       		<geometry>
         		<mesh filename="package://antares_model/meshes/pelvis_r_visual_simple.stl"/>
       		</geometry>
       		<material name="white"/>
	   </visual>
       <collision>
        <origin rpy="0 0 0" xyz="0 0 0"/>
        <geometry>
           <box size="0,053 0,064 0,04"/>
        </geometry>
     </collision>
   </link>
   
   <joint name="pelvis_roll_l" type="continuous">
     <origin rpy="0 0 0" xyz="-0.00017 0 -0.01252"/>
     <parent link="pelvis_l"/>
     <child link="pelvis_l_servos"/>
     <axis xyz="0 1 0"/>
   </joint>

   <link name="pelvis_l_servos">
	   <visual>
		<origin rpy="0 0 0" xyz="-0,26206 0,099753 -0,41768"/>
       		<geometry>
         		<mesh filename="package://antares_model/meshes/pelvis_servos_l_visual_simple.stl"/>
       		</geometry>
       		<material name="white"/>
	   </visual>
       <collision>
        <origin rpy="0 0 0" xyz="0 0,023 -0,017"/>
        <geometry>
           <box size="0,039 0,105 0,062"/>
        </geometry>
     </collision>
   </link>
   
   <joint name="pelvis_roll_r" type="continuous">
     <origin rpy="0 0 0" xyz="0.00017 0 -0.01252"/>
     <parent link="pelvis_r"/>
     <child link="pelvis_r_servos"/>
     <axis xyz="0 1 0"/>
   </joint>

   <link name="pelvis_r_servos">
	   <visual>
		<origin rpy="0 0 0" xyz="-0,093392 0,099753 -0,41768"/>
       		<geometry>
         		<mesh filename="package://antares_model/meshes/pelvis_servos_r_visual_simple.stl"/>
       		</geometry>
       		<material name="white"/>
	   </visual>
       <collision>
        <origin rpy="0 0 0" xyz="0 0,023 -0,017"/>
        <geometry>
           <box size="0,039 0,105 0,062"/>
        </geometry>
     </collision>
   </link>
   
<joint name="pelvis_pitch_l" type="continuous">
     <origin rpy="0 0 0" xyz="0 0 0"/>
     <parent link="pelvis_l_servos"/>
     <child link="hip_l"/>
     <axis xyz="1 0 0"/>
   </joint>

   <link name="hip_l">
	   <visual>
		<origin rpy="0 0 0" xyz="-0,26206 0,099753 -0,41768"/>
       		<geometry>
         		<mesh filename="package://antares_model/meshes/hip_l_visual_simple.stl"/>
       		</geometry>
       		<material name="white"/>
	   </visual>
     <collision>
        <origin rpy="-0,2967 0 0" xyz="0 -0,025 -0,08"/>
        <geometry>
           <box size="0,05 0,044 0,21"/>
        </geometry>
     </collision>
   </link>
   
   <joint name="pelvis_pitch_r" type="continuous">
     <origin rpy="0 0 0" xyz="0 0 0"/>
     <parent link="pelvis_r_servos"/>
     <child link="hip_r"/>
     <axis xyz="1 0 0"/>
   </joint>

   <link name="hip_r">
	   <visual>
		<origin rpy="0 0 0" xyz="-0,093392 0,099753 -0,41768"/>
       		<geometry>
         		<mesh filename="package://antares_model/meshes/hip_r_visual_simple.stl"/>
       		</geometry>
       		<material name="white"/>
	   </visual>
       <collision>
        <origin rpy="-0,2967 0 0" xyz="0 -0,025 -0,08"/>
        <geometry>
           <box size="0,05 0,044 0,21"/>
        </geometry>
     </collision>
   </link>
   
    <joint name="knee_pitch_l" type="continuous">
     <origin rpy="0 0 0" xyz="0 0.001 -0.1759"/>
     <parent link="hip_l"/>
     <child link="calf_l"/>
     <axis xyz="1 0 0"/>
   </joint>

   <link name="calf_l">
	   <visual>
		<origin rpy="0 0 0" xyz="-0,26206 0,097653 -0,24748"/>
       		<geometry>
         		<mesh filename="package://antares_model/meshes/calf_l_visual_simple.stl"/>
       		</geometry>
       		<material name="white"/>
	   </visual>
     <collision>
        <origin rpy="0 0 0" xyz="0 0 -0,082"/>
        <geometry>
           <box size="0,087 0,04 0,19"/>
        </geometry>
     </collision>
   </link>
   
    <joint name="knee_pitch_r" type="continuous">
     <origin rpy="0 0 0" xyz="0 0.001 -0.1759"/>
     <parent link="hip_r"/>
     <child link="calf_r"/>
     <axis xyz="1 0 0"/>
   </joint>

   <link name="calf_r">
	   <visual>
		<origin rpy="0 0 0" xyz="-0,093392 0,097653 -0,24748"/>
       		<geometry>
         		<mesh filename="package://antares_model/meshes/calf_r_visual_simple.stl"/>
       		</geometry>
       		<material name="white"/>
	   </visual>
     <collision>
        <origin rpy="0 0 0" xyz="0 0 -0,082"/>
        <geometry>
           <box size="0,087 0,04 0,19"/>
        </geometry>
     </collision>
   </link>
   
   <joint name="ankle_pitch_l" type="continuous">
     <origin rpy="0 0 0" xyz="0 0.003 -0.170075"/>
     <parent link="calf_l"/>
     <child link="ankle_l_servos"/>
     <axis xyz="1 0 0"/>
   </joint>

   <link name="ankle_l_servos">
	   <visual>
		<origin rpy="0 0 0" xyz="-0,26206 0,093989 -0,069705"/>
       		<geometry>
         		<mesh filename="package://antares_model/meshes/ankle_l_servos_visual_simple.stl"/>
       		</geometry>
       		<material name="white"/>
	   </visual>
      <collision>
        <origin rpy="0 0 0" xyz="0 0,02 -0,017"/>
        <geometry>
           <box size="0,045 0,1 0,06"/>
        </geometry>
     </collision>
   </link>
   
   <joint name="ankle_pitch_r" type="continuous">
     <origin rpy="0 0 0" xyz="0 0.003 -0.170075"/>
     <parent link="calf_r"/>
     <child link="ankle_r_servos"/>
     <axis xyz="1 0 0"/>
   </joint>

   <link name="ankle_r_servos">
	   <visual>
		<origin rpy="0 0 0" xyz="-0,093392 0,093989 -0,069705"/>
       		<geometry>
         		<mesh filename="package://antares_model/meshes/ankle_r_servos_visual_simple.stl"/>
       		</geometry>
       		<material name="white"/>
	   </visual>
     <collision>
        <origin rpy="0 0 0" xyz="0 0,02 -0,017"/>
        <geometry>
           <box size="0,045 0,1 0,06"/>
        </geometry>
     </collision>
   </link>
   
    <joint name="ankle_roll_l" type="continuous">
     <origin rpy="0 0 0" xyz="0 0 0"/>
     <parent link="ankle_l_servos"/>
     <child link="ankle_l"/>
     <axis xyz="0 1 0"/>
   </joint>

   <link name="ankle_l">
	   <visual>
		<origin rpy="0 0 0" xyz="-0,26306 0,093987 -0,071705"/>
       		<geometry>
         		<mesh filename="package://antares_model/meshes/ankle_l_visual_simple.stl"/>
       		</geometry>
       		<material name="white"/>
	   </visual>
     <collision>
        <origin rpy="0 0 0" xyz="0,004 -0,005 -0,0572"/>
        <geometry>
           <box size="0,105 0,2 0,01"/>
        </geometry>
     </collision>
   </link>
   
    <joint name="ankle_roll_r" type="continuous">
     <origin rpy="0 0 0" xyz="0 0 0"/>
     <parent link="ankle_r_servos"/>
     <child link="ankle_r"/>
     <axis xyz="0 1 0"/>
   </joint>

   <link name="ankle_r">
	   <visual>
		<origin rpy="0 0 0" xyz="-0,092392 0,093987 -0,071705"/>
       		<geometry>
         		<mesh filename="package://antares_model/meshes/ankle_r_visual_simple.stl"/>
       		</geometry>
       		<material name="white"/>
	   </visual>
     <collision>
        <origin rpy="0 0 0" xyz="-0,004 -0,005 -0,0572"/>
        <geometry>
           <box size="0,105 0,2 0,01"/>
        </geometry>
     </collision>
   </link>
   
   <joint name="shoulder_pitch_l" type="continuous">
     <origin rpy="0 0 0" xyz="0.29596 -0.099723 0.64948"/>
     <parent link="base_link"/>
     <child link="shoulder_l"/>
     <axis xyz="1 0 0"/>
   </joint>

   <link name="shoulder_l">
	   <visual>
		<origin rpy="0 0 0" xyz="-0,29596 0,099723 -0,64948"/>
       		<geometry>
         		<mesh filename="package://antares_model/meshes/upper_shoulder_l_visual_simple.stl"/>
       		</geometry>
       		<material name="white"/>
	   </visual>
     <collision>
        <origin rpy="0 0 0" xyz="0,021 0 0"/>
        <geometry>
           <box size="0,04 0,044 0,03"/>
        </geometry>
     </collision>
   </link>
   
    <joint name="shoulder_pitch_r" type="continuous">
     <origin rpy="0 0 0" xyz="0.059497 -0.099723 0.64948"/>
     <parent link="base_link"/>
     <child link="shoulder_r"/>
     <axis xyz="1 0 0"/>
   </joint>

   <link name="shoulder_r">
	   <visual>
		<origin rpy="0 0 0" xyz="-0,059497 0,099723 -0,64948"/>
       		<geometry>
         		<mesh filename="package://antares_model/meshes/upper_shoulder_r_visual_simple.stl"/>
       		</geometry>
       		<material name="white"/>
	   </visual>
     <collision>
        <origin rpy="0 0 0" xyz="-0,021 0 0"/>
        <geometry>
           <box size="0,04 0,044 0,03"/>
        </geometry>
     </collision>
   </link>
   
    <joint name="shoulder_roll_l" type="continuous">
     <origin rpy="0 0 0" xyz="0.03287 -0.00003 0.00003"/>
     <parent link="shoulder_l"/>
     <child link="lower_shoulder_l"/>
     <axis xyz="0 1 0"/>
   </joint>

   <link name="lower_shoulder_l">
	   <visual>
		<origin rpy="0 0 0" xyz="-0,32890 0,099953 -0,64945"/>
       		<geometry>
         		<mesh filename="package://antares_model/meshes/lower_shoulder_l_visual_simple.stl"/>
       		</geometry>
       		<material name="white"/>
	   </visual>
     <collision>
        <origin rpy="0 0 0" xyz="0 0 -0,07"/>
        <geometry>
           <box size="0,036 0,036 0,17"/>
        </geometry>
     </collision>
   </link>
   
   <joint name="shoulder_roll_r" type="continuous">
     <origin rpy="0 0 0" xyz="-0.03287 -0.00003 0.00003"/>
     <parent link="shoulder_r"/>
     <child link="lower_shoulder_r"/>
     <axis xyz="0 1 0"/>
   </joint>

   <link name="lower_shoulder_r">
	   <visual>
		<origin rpy="0 0 0" xyz="-0,026628 0,099953 -0,64945"/>
       		<geometry>
         		<mesh filename="package://antares_model/meshes/lower_shoulder_r_visual_simple.stl"/>
       		</geometry>
       		<material name="white"/>
	   </visual>
     <collision>
        <origin rpy="0 0 0" xyz="0 0 -0,07"/>
        <geometry>
           <box size="0,036 0,036 0,17"/>
        </geometry>
     </collision>
   </link>

    <joint name="elbow_l" type="continuous">
     <origin rpy="0 0 0" xyz="0 0 -0.14048"/>
     <parent link="lower_shoulder_l"/>
     <child link="forearm_l"/>
     <axis xyz="1 0 0"/>
   </joint>

   <link name="forearm_l">
	   <visual>
		<origin rpy="0 0 0" xyz="-0,32790 0,099760 -0,50750"/>
       		<geometry>
         		<mesh filename="package://antares_model/meshes/forearm_l_visual_simple.stl"/>
       		</geometry>
       		<material name="white"/>
	   </visual>
     <collision>
        <origin rpy="0 0 0" xyz="0 0 -0,11"/>
        <geometry>
           <box size="0,03 0,0465 0,16"/>
        </geometry>
     </collision>
   </link>
   
    <joint name="elbow_r" type="continuous">
     <origin rpy="0 0 0" xyz="0 0 -0.14048"/>
     <parent link="lower_shoulder_r"/>
     <child link="forearm_r"/>
     <axis xyz="1 0 0"/>
   </joint>

   <link name="forearm_r">
	   <visual>
		<origin rpy="0 0 0" xyz="-0,025628 0,099760 -0,50750"/>
       		<geometry>
         		<mesh filename="package://antares_model/meshes/forearm_r_visual_simple.stl"/>
       		</geometry>
       		<material name="white"/>
	   </visual>
     <collision>
        <origin rpy="0 0 0" xyz="0 0 -0,11"/>
        <geometry>
           <box size="0,03 0,0465 0,16"/>
        </geometry>
     </collision>
   </link>



</robot>
